<?xml version="1.0" encoding="UTF-8"?>
<testng-results ignored="0" total="15" passed="7" failed="5" skipped="3">
  <reporter-output>
  </reporter-output>
  <suite started-at="2022-02-03T01:18:06 IST" name="EmployeesRestAPISuite" finished-at="2022-02-03T01:18:25 IST" duration-ms="18396">
    <groups>
    </groups>
    <test started-at="2022-02-03T01:18:06 IST" name="EmployeesRestAPITests" finished-at="2022-02-03T01:18:25 IST" duration-ms="18396">
      <class name="com.employeeAPI.testCases.GetAllEmployees">
        <test-method is-config="true" signature="setUp()[pri:0, instance:com.employeeAPI.testCases.GetAllEmployees@4d465b11]" started-at="2022-02-03T01:18:06 IST" name="setUp" finished-at="2022-02-03T01:18:07 IST" duration-ms="112" status="PASS">
          <reporter-output>
          </reporter-output>
        </test-method> <!-- setUp -->
        <test-method is-config="true" signature="getAllEmployees()[pri:0, instance:com.employeeAPI.testCases.GetAllEmployees@4d465b11]" started-at="2022-02-03T01:18:07 IST" name="getAllEmployees" finished-at="2022-02-03T01:18:13 IST" duration-ms="6311" status="PASS">
          <reporter-output>
          </reporter-output>
        </test-method> <!-- getAllEmployees -->
        <test-method signature="validateResponseBody()[pri:0, instance:com.employeeAPI.testCases.GetAllEmployees@4d465b11]" started-at="2022-02-03T01:18:13 IST" name="validateResponseBody" finished-at="2022-02-03T01:18:13 IST" duration-ms="258" status="PASS">
          <reporter-output>
          </reporter-output>
        </test-method> <!-- validateResponseBody -->
        <test-method signature="validateResponseTime()[pri:0, instance:com.employeeAPI.testCases.GetAllEmployees@4d465b11]" started-at="2022-02-03T01:18:13 IST" name="validateResponseTime" finished-at="2022-02-03T01:18:13 IST" duration-ms="2" status="PASS">
          <reporter-output>
          </reporter-output>
        </test-method> <!-- validateResponseTime -->
        <test-method signature="validateStatusCode()[pri:0, instance:com.employeeAPI.testCases.GetAllEmployees@4d465b11]" started-at="2022-02-03T01:18:13 IST" name="validateStatusCode" finished-at="2022-02-03T01:18:13 IST" duration-ms="4" status="FAIL">
          <exception class="java.lang.AssertionError">
            <message>
              <![CDATA[expected [200] but found [429]]]>
            </message>
            <full-stacktrace>
              <![CDATA[java.lang.AssertionError: expected [200] but found [429]
at org.testng.Assert.fail(Assert.java:99)
at org.testng.Assert.failNotEquals(Assert.java:1037)
at org.testng.Assert.assertEqualsImpl(Assert.java:140)
at org.testng.Assert.assertEquals(Assert.java:122)
at org.testng.Assert.assertEquals(Assert.java:907)
at org.testng.Assert.assertEquals(Assert.java:917)
at com.employeeAPI.testCases.GetAllEmployees.validateStatusCode(GetAllEmployees.java:40)
at java.base/jdk.internal.reflect.NativeMethodAccessorImpl.invoke0(Native Method)
at java.base/jdk.internal.reflect.NativeMethodAccessorImpl.invoke(NativeMethodAccessorImpl.java:62)
at java.base/jdk.internal.reflect.DelegatingMethodAccessorImpl.invoke(DelegatingMethodAccessorImpl.java:43)
at java.base/java.lang.reflect.Method.invoke(Method.java:566)
at org.testng.internal.MethodInvocationHelper.invokeMethod(MethodInvocationHelper.java:133)
at org.testng.internal.TestInvoker.invokeMethod(TestInvoker.java:598)
at org.testng.internal.TestInvoker.invokeTestMethod(TestInvoker.java:173)
at org.testng.internal.MethodRunner.runInSequence(MethodRunner.java:46)
at org.testng.internal.TestInvoker$MethodInvocationAgent.invoke(TestInvoker.java:824)
at org.testng.internal.TestInvoker.invokeTestMethods(TestInvoker.java:146)
at org.testng.internal.TestMethodWorker.invokeTestMethods(TestMethodWorker.java:146)
at org.testng.internal.TestMethodWorker.run(TestMethodWorker.java:128)
at java.base/java.util.ArrayList.forEach(ArrayList.java:1541)
at org.testng.TestRunner.privateRun(TestRunner.java:794)
at org.testng.TestRunner.run(TestRunner.java:596)
at org.testng.SuiteRunner.runTest(SuiteRunner.java:377)
at org.testng.SuiteRunner.runSequentially(SuiteRunner.java:371)
at org.testng.SuiteRunner.privateRun(SuiteRunner.java:332)
at org.testng.SuiteRunner.run(SuiteRunner.java:276)
at org.testng.SuiteRunnerWorker.runSuite(SuiteRunnerWorker.java:53)
at org.testng.SuiteRunnerWorker.run(SuiteRunnerWorker.java:96)
at org.testng.TestNG.runSuitesSequentially(TestNG.java:1212)
at org.testng.TestNG.runSuitesLocally(TestNG.java:1134)
at org.testng.TestNG.runSuites(TestNG.java:1063)
at org.testng.TestNG.run(TestNG.java:1031)
at org.testng.remote.AbstractRemoteTestNG.run(AbstractRemoteTestNG.java:115)
at org.testng.remote.RemoteTestNG.initAndRun(RemoteTestNG.java:251)
at org.testng.remote.RemoteTestNG.main(RemoteTestNG.java:77)
]]>
            </full-stacktrace>
          </exception> <!-- java.lang.AssertionError -->
          <reporter-output>
          </reporter-output>
        </test-method> <!-- validateStatusCode -->
        <test-method is-config="true" signature="tearDown()[pri:0, instance:com.employeeAPI.testCases.GetAllEmployees@4d465b11]" started-at="2022-02-03T01:18:13 IST" name="tearDown" finished-at="2022-02-03T01:18:13 IST" duration-ms="1" status="PASS">
          <reporter-output>
          </reporter-output>
        </test-method> <!-- tearDown -->
      </class> <!-- com.employeeAPI.testCases.GetAllEmployees -->
      <class name="com.employeeAPI.testCases.ModifyEmployee">
        <test-method is-config="true" signature="setUp()[pri:0, instance:com.employeeAPI.testCases.ModifyEmployee@22ef9844]" started-at="2022-02-03T01:18:20 IST" name="setUp" finished-at="2022-02-03T01:18:20 IST" duration-ms="3" status="PASS">
          <reporter-output>
          </reporter-output>
        </test-method> <!-- setUp -->
        <test-method is-config="true" signature="modifyEmployees()[pri:0, instance:com.employeeAPI.testCases.ModifyEmployee@22ef9844]" started-at="2022-02-03T01:18:20 IST" name="modifyEmployees" finished-at="2022-02-03T01:18:24 IST" duration-ms="4047" status="PASS">
          <reporter-output>
          </reporter-output>
        </test-method> <!-- modifyEmployees -->
        <test-method signature="validateResponseBody()[pri:0, instance:com.employeeAPI.testCases.ModifyEmployee@22ef9844]" started-at="2022-02-03T01:18:24 IST" name="validateResponseBody" finished-at="2022-02-03T01:18:24 IST" duration-ms="2" status="FAIL">
          <exception class="java.lang.AssertionError">
            <message>
              <![CDATA[expected [true] but found [false]]]>
            </message>
            <full-stacktrace>
              <![CDATA[java.lang.AssertionError: expected [true] but found [false]
at org.testng.Assert.fail(Assert.java:99)
at org.testng.Assert.failNotEquals(Assert.java:1037)
at org.testng.Assert.assertTrue(Assert.java:45)
at org.testng.Assert.assertTrue(Assert.java:55)
at com.employeeAPI.testCases.ModifyEmployee.validateResponseBody(ModifyEmployee.java:47)
at java.base/jdk.internal.reflect.NativeMethodAccessorImpl.invoke0(Native Method)
at java.base/jdk.internal.reflect.NativeMethodAccessorImpl.invoke(NativeMethodAccessorImpl.java:62)
at java.base/jdk.internal.reflect.DelegatingMethodAccessorImpl.invoke(DelegatingMethodAccessorImpl.java:43)
at java.base/java.lang.reflect.Method.invoke(Method.java:566)
at org.testng.internal.MethodInvocationHelper.invokeMethod(MethodInvocationHelper.java:133)
at org.testng.internal.TestInvoker.invokeMethod(TestInvoker.java:598)
at org.testng.internal.TestInvoker.invokeTestMethod(TestInvoker.java:173)
at org.testng.internal.MethodRunner.runInSequence(MethodRunner.java:46)
at org.testng.internal.TestInvoker$MethodInvocationAgent.invoke(TestInvoker.java:824)
at org.testng.internal.TestInvoker.invokeTestMethods(TestInvoker.java:146)
at org.testng.internal.TestMethodWorker.invokeTestMethods(TestMethodWorker.java:146)
at org.testng.internal.TestMethodWorker.run(TestMethodWorker.java:128)
at java.base/java.util.ArrayList.forEach(ArrayList.java:1541)
at org.testng.TestRunner.privateRun(TestRunner.java:794)
at org.testng.TestRunner.run(TestRunner.java:596)
at org.testng.SuiteRunner.runTest(SuiteRunner.java:377)
at org.testng.SuiteRunner.runSequentially(SuiteRunner.java:371)
at org.testng.SuiteRunner.privateRun(SuiteRunner.java:332)
at org.testng.SuiteRunner.run(SuiteRunner.java:276)
at org.testng.SuiteRunnerWorker.runSuite(SuiteRunnerWorker.java:53)
at org.testng.SuiteRunnerWorker.run(SuiteRunnerWorker.java:96)
at org.testng.TestNG.runSuitesSequentially(TestNG.java:1212)
at org.testng.TestNG.runSuitesLocally(TestNG.java:1134)
at org.testng.TestNG.runSuites(TestNG.java:1063)
at org.testng.TestNG.run(TestNG.java:1031)
at org.testng.remote.AbstractRemoteTestNG.run(AbstractRemoteTestNG.java:115)
at org.testng.remote.RemoteTestNG.initAndRun(RemoteTestNG.java:251)
at org.testng.remote.RemoteTestNG.main(RemoteTestNG.java:77)
]]>
            </full-stacktrace>
          </exception> <!-- java.lang.AssertionError -->
          <reporter-output>
          </reporter-output>
        </test-method> <!-- validateResponseBody -->
        <test-method signature="validateResponseTime()[pri:0, instance:com.employeeAPI.testCases.ModifyEmployee@22ef9844]" started-at="2022-02-03T01:18:24 IST" name="validateResponseTime" finished-at="2022-02-03T01:18:24 IST" duration-ms="2" status="PASS">
          <reporter-output>
          </reporter-output>
        </test-method> <!-- validateResponseTime -->
        <test-method signature="validateStatusCode()[pri:0, instance:com.employeeAPI.testCases.ModifyEmployee@22ef9844]" started-at="2022-02-03T01:18:24 IST" name="validateStatusCode" finished-at="2022-02-03T01:18:24 IST" duration-ms="3" status="FAIL">
          <exception class="java.lang.AssertionError">
            <message>
              <![CDATA[expected [200] but found [429]]]>
            </message>
            <full-stacktrace>
              <![CDATA[java.lang.AssertionError: expected [200] but found [429]
at org.testng.Assert.fail(Assert.java:99)
at org.testng.Assert.failNotEquals(Assert.java:1037)
at org.testng.Assert.assertEqualsImpl(Assert.java:140)
at org.testng.Assert.assertEquals(Assert.java:122)
at org.testng.Assert.assertEquals(Assert.java:907)
at org.testng.Assert.assertEquals(Assert.java:917)
at com.employeeAPI.testCases.ModifyEmployee.validateStatusCode(ModifyEmployee.java:58)
at java.base/jdk.internal.reflect.NativeMethodAccessorImpl.invoke0(Native Method)
at java.base/jdk.internal.reflect.NativeMethodAccessorImpl.invoke(NativeMethodAccessorImpl.java:62)
at java.base/jdk.internal.reflect.DelegatingMethodAccessorImpl.invoke(DelegatingMethodAccessorImpl.java:43)
at java.base/java.lang.reflect.Method.invoke(Method.java:566)
at org.testng.internal.MethodInvocationHelper.invokeMethod(MethodInvocationHelper.java:133)
at org.testng.internal.TestInvoker.invokeMethod(TestInvoker.java:598)
at org.testng.internal.TestInvoker.invokeTestMethod(TestInvoker.java:173)
at org.testng.internal.MethodRunner.runInSequence(MethodRunner.java:46)
at org.testng.internal.TestInvoker$MethodInvocationAgent.invoke(TestInvoker.java:824)
at org.testng.internal.TestInvoker.invokeTestMethods(TestInvoker.java:146)
at org.testng.internal.TestMethodWorker.invokeTestMethods(TestMethodWorker.java:146)
at org.testng.internal.TestMethodWorker.run(TestMethodWorker.java:128)
at java.base/java.util.ArrayList.forEach(ArrayList.java:1541)
at org.testng.TestRunner.privateRun(TestRunner.java:794)
at org.testng.TestRunner.run(TestRunner.java:596)
at org.testng.SuiteRunner.runTest(SuiteRunner.java:377)
at org.testng.SuiteRunner.runSequentially(SuiteRunner.java:371)
at org.testng.SuiteRunner.privateRun(SuiteRunner.java:332)
at org.testng.SuiteRunner.run(SuiteRunner.java:276)
at org.testng.SuiteRunnerWorker.runSuite(SuiteRunnerWorker.java:53)
at org.testng.SuiteRunnerWorker.run(SuiteRunnerWorker.java:96)
at org.testng.TestNG.runSuitesSequentially(TestNG.java:1212)
at org.testng.TestNG.runSuitesLocally(TestNG.java:1134)
at org.testng.TestNG.runSuites(TestNG.java:1063)
at org.testng.TestNG.run(TestNG.java:1031)
at org.testng.remote.AbstractRemoteTestNG.run(AbstractRemoteTestNG.java:115)
at org.testng.remote.RemoteTestNG.initAndRun(RemoteTestNG.java:251)
at org.testng.remote.RemoteTestNG.main(RemoteTestNG.java:77)
]]>
            </full-stacktrace>
          </exception> <!-- java.lang.AssertionError -->
          <reporter-output>
          </reporter-output>
        </test-method> <!-- validateStatusCode -->
        <test-method is-config="true" signature="tearDown()[pri:0, instance:com.employeeAPI.testCases.ModifyEmployee@22ef9844]" started-at="2022-02-03T01:18:24 IST" name="tearDown" finished-at="2022-02-03T01:18:24 IST" duration-ms="1" status="PASS">
          <reporter-output>
          </reporter-output>
        </test-method> <!-- tearDown -->
      </class> <!-- com.employeeAPI.testCases.ModifyEmployee -->
      <class name="com.employeeAPI.testCases.DeleteEmployee">
        <test-method is-config="true" signature="setUp()[pri:0, instance:com.employeeAPI.testCases.DeleteEmployee@3b6ddd1d]" started-at="2022-02-03T01:18:24 IST" name="setUp" finished-at="2022-02-03T01:18:24 IST" duration-ms="3" status="PASS">
          <reporter-output>
          </reporter-output>
        </test-method> <!-- setUp -->
        <test-method is-config="true" signature="deleteEmployee()[pri:0, instance:com.employeeAPI.testCases.DeleteEmployee@3b6ddd1d]" started-at="2022-02-03T01:18:24 IST" name="deleteEmployee" finished-at="2022-02-03T01:18:25 IST" duration-ms="1185" status="FAIL">
          <exception class="io.restassured.path.json.exception.JsonPathException">
            <message>
              <![CDATA[Failed to parse the JSON document]]>
            </message>
            <full-stacktrace>
              <![CDATA[io.restassured.path.json.exception.JsonPathException: Failed to parse the JSON document
at io.restassured.path.json.JsonPath$ExceptionCatcher.invoke(JsonPath.java:1002)
at io.restassured.path.json.JsonPath$4.doParseWith(JsonPath.java:967)
at io.restassured.path.json.JsonPath$JsonParser.parseWith(JsonPath.java:1047)
at io.restassured.path.json.JsonPath.get(JsonPath.java:202)
at com.employeeAPI.testCases.DeleteEmployee.deleteEmployee(DeleteEmployee.java:24)
at java.base/jdk.internal.reflect.NativeMethodAccessorImpl.invoke0(Native Method)
at java.base/jdk.internal.reflect.NativeMethodAccessorImpl.invoke(NativeMethodAccessorImpl.java:62)
at java.base/jdk.internal.reflect.DelegatingMethodAccessorImpl.invoke(DelegatingMethodAccessorImpl.java:43)
at java.base/java.lang.reflect.Method.invoke(Method.java:566)
at org.testng.internal.MethodInvocationHelper.invokeMethod(MethodInvocationHelper.java:133)
at org.testng.internal.MethodInvocationHelper.invokeMethodConsideringTimeout(MethodInvocationHelper.java:62)
at org.testng.internal.ConfigInvoker.invokeConfigurationMethod(ConfigInvoker.java:385)
at org.testng.internal.ConfigInvoker.invokeConfigurations(ConfigInvoker.java:321)
at org.testng.internal.TestMethodWorker.invokeBeforeClassMethods(TestMethodWorker.java:176)
at org.testng.internal.TestMethodWorker.run(TestMethodWorker.java:122)
at java.base/java.util.ArrayList.forEach(ArrayList.java:1541)
at org.testng.TestRunner.privateRun(TestRunner.java:794)
at org.testng.TestRunner.run(TestRunner.java:596)
at org.testng.SuiteRunner.runTest(SuiteRunner.java:377)
at org.testng.SuiteRunner.runSequentially(SuiteRunner.java:371)
at org.testng.SuiteRunner.privateRun(SuiteRunner.java:332)
at org.testng.SuiteRunner.run(SuiteRunner.java:276)
at org.testng.SuiteRunnerWorker.runSuite(SuiteRunnerWorker.java:53)
at org.testng.SuiteRunnerWorker.run(SuiteRunnerWorker.java:96)
at org.testng.TestNG.runSuitesSequentially(TestNG.java:1212)
at org.testng.TestNG.runSuitesLocally(TestNG.java:1134)
at org.testng.TestNG.runSuites(TestNG.java:1063)
at org.testng.TestNG.run(TestNG.java:1031)
at org.testng.remote.AbstractRemoteTestNG.run(AbstractRemoteTestNG.java:115)
at org.testng.remote.RemoteTestNG.initAndRun(RemoteTestNG.java:251)
at org.testng.remote.RemoteTestNG.main(RemoteTestNG.java:77)
Caused by: groovy.json.JsonException: Lexing failed on line: 1, column: 1, while reading '<', no possible valid JSON value or punctuation could be recognized.
at groovy.json.JsonLexer.nextToken(JsonLexer.java:86)
at groovy.json.JsonLexer$nextToken.call(Unknown Source)
at org.codehaus.groovy.runtime.callsite.CallSiteArray.defaultCall(CallSiteArray.java:47)
at org.codehaus.groovy.runtime.callsite.AbstractCallSite.call(AbstractCallSite.java:125)
at org.codehaus.groovy.runtime.callsite.AbstractCallSite.call(AbstractCallSite.java:130)
at io.restassured.internal.path.json.ConfigurableJsonSlurper.parse(ConfigurableJsonSlurper.groovy:97)
at io.restassured.internal.path.json.ConfigurableJsonSlurper$parse.callCurrent(Unknown Source)
at org.codehaus.groovy.runtime.callsite.CallSiteArray.defaultCallCurrent(CallSiteArray.java:51)
at org.codehaus.groovy.runtime.callsite.AbstractCallSite.callCurrent(AbstractCallSite.java:171)
at org.codehaus.groovy.runtime.callsite.AbstractCallSite.callCurrent(AbstractCallSite.java:185)
at io.restassured.internal.path.json.ConfigurableJsonSlurper.parseText(ConfigurableJsonSlurper.groovy:83)
at io.restassured.path.json.JsonPath$4$1.method(JsonPath.java:965)
at io.restassured.path.json.JsonPath$ExceptionCatcher.invoke(JsonPath.java:1000)
... 30 more
]]>
            </full-stacktrace>
          </exception> <!-- io.restassured.path.json.exception.JsonPathException -->
          <reporter-output>
          </reporter-output>
        </test-method> <!-- deleteEmployee -->
        <test-method signature="validateResponseBody()[pri:0, instance:com.employeeAPI.testCases.DeleteEmployee@3b6ddd1d]" started-at="2022-02-03T01:18:25 IST" name="validateResponseBody" finished-at="2022-02-03T01:18:25 IST" duration-ms="0" status="SKIP">
          <exception class="io.restassured.path.json.exception.JsonPathException">
            <message>
              <![CDATA[Failed to parse the JSON document]]>
            </message>
            <full-stacktrace>
              <![CDATA[io.restassured.path.json.exception.JsonPathException: Failed to parse the JSON document
at io.restassured.path.json.JsonPath$ExceptionCatcher.invoke(JsonPath.java:1002)
at io.restassured.path.json.JsonPath$4.doParseWith(JsonPath.java:967)
at io.restassured.path.json.JsonPath$JsonParser.parseWith(JsonPath.java:1047)
at io.restassured.path.json.JsonPath.get(JsonPath.java:202)
at com.employeeAPI.testCases.DeleteEmployee.deleteEmployee(DeleteEmployee.java:24)
at java.base/jdk.internal.reflect.NativeMethodAccessorImpl.invoke0(Native Method)
at java.base/jdk.internal.reflect.NativeMethodAccessorImpl.invoke(NativeMethodAccessorImpl.java:62)
at java.base/jdk.internal.reflect.DelegatingMethodAccessorImpl.invoke(DelegatingMethodAccessorImpl.java:43)
at java.base/java.lang.reflect.Method.invoke(Method.java:566)
at org.testng.internal.MethodInvocationHelper.invokeMethod(MethodInvocationHelper.java:133)
at org.testng.internal.MethodInvocationHelper.invokeMethodConsideringTimeout(MethodInvocationHelper.java:62)
at org.testng.internal.ConfigInvoker.invokeConfigurationMethod(ConfigInvoker.java:385)
at org.testng.internal.ConfigInvoker.invokeConfigurations(ConfigInvoker.java:321)
at org.testng.internal.TestMethodWorker.invokeBeforeClassMethods(TestMethodWorker.java:176)
at org.testng.internal.TestMethodWorker.run(TestMethodWorker.java:122)
at java.base/java.util.ArrayList.forEach(ArrayList.java:1541)
at org.testng.TestRunner.privateRun(TestRunner.java:794)
at org.testng.TestRunner.run(TestRunner.java:596)
at org.testng.SuiteRunner.runTest(SuiteRunner.java:377)
at org.testng.SuiteRunner.runSequentially(SuiteRunner.java:371)
at org.testng.SuiteRunner.privateRun(SuiteRunner.java:332)
at org.testng.SuiteRunner.run(SuiteRunner.java:276)
at org.testng.SuiteRunnerWorker.runSuite(SuiteRunnerWorker.java:53)
at org.testng.SuiteRunnerWorker.run(SuiteRunnerWorker.java:96)
at org.testng.TestNG.runSuitesSequentially(TestNG.java:1212)
at org.testng.TestNG.runSuitesLocally(TestNG.java:1134)
at org.testng.TestNG.runSuites(TestNG.java:1063)
at org.testng.TestNG.run(TestNG.java:1031)
at org.testng.remote.AbstractRemoteTestNG.run(AbstractRemoteTestNG.java:115)
at org.testng.remote.RemoteTestNG.initAndRun(RemoteTestNG.java:251)
at org.testng.remote.RemoteTestNG.main(RemoteTestNG.java:77)
Caused by: groovy.json.JsonException: Lexing failed on line: 1, column: 1, while reading '<', no possible valid JSON value or punctuation could be recognized.
at groovy.json.JsonLexer.nextToken(JsonLexer.java:86)
at groovy.json.JsonLexer$nextToken.call(Unknown Source)
at org.codehaus.groovy.runtime.callsite.CallSiteArray.defaultCall(CallSiteArray.java:47)
at org.codehaus.groovy.runtime.callsite.AbstractCallSite.call(AbstractCallSite.java:125)
at org.codehaus.groovy.runtime.callsite.AbstractCallSite.call(AbstractCallSite.java:130)
at io.restassured.internal.path.json.ConfigurableJsonSlurper.parse(ConfigurableJsonSlurper.groovy:97)
at io.restassured.internal.path.json.ConfigurableJsonSlurper$parse.callCurrent(Unknown Source)
at org.codehaus.groovy.runtime.callsite.CallSiteArray.defaultCallCurrent(CallSiteArray.java:51)
at org.codehaus.groovy.runtime.callsite.AbstractCallSite.callCurrent(AbstractCallSite.java:171)
at org.codehaus.groovy.runtime.callsite.AbstractCallSite.callCurrent(AbstractCallSite.java:185)
at io.restassured.internal.path.json.ConfigurableJsonSlurper.parseText(ConfigurableJsonSlurper.groovy:83)
at io.restassured.path.json.JsonPath$4$1.method(JsonPath.java:965)
at io.restassured.path.json.JsonPath$ExceptionCatcher.invoke(JsonPath.java:1000)
... 30 more
]]>
            </full-stacktrace>
          </exception> <!-- io.restassured.path.json.exception.JsonPathException -->
          <reporter-output>
          </reporter-output>
        </test-method> <!-- validateResponseBody -->
        <test-method signature="validateResponseTime()[pri:0, instance:com.employeeAPI.testCases.DeleteEmployee@3b6ddd1d]" started-at="2022-02-03T01:18:25 IST" name="validateResponseTime" finished-at="2022-02-03T01:18:25 IST" duration-ms="0" status="SKIP">
          <exception class="io.restassured.path.json.exception.JsonPathException">
            <message>
              <![CDATA[Failed to parse the JSON document]]>
            </message>
            <full-stacktrace>
              <![CDATA[io.restassured.path.json.exception.JsonPathException: Failed to parse the JSON document
at io.restassured.path.json.JsonPath$ExceptionCatcher.invoke(JsonPath.java:1002)
at io.restassured.path.json.JsonPath$4.doParseWith(JsonPath.java:967)
at io.restassured.path.json.JsonPath$JsonParser.parseWith(JsonPath.java:1047)
at io.restassured.path.json.JsonPath.get(JsonPath.java:202)
at com.employeeAPI.testCases.DeleteEmployee.deleteEmployee(DeleteEmployee.java:24)
at java.base/jdk.internal.reflect.NativeMethodAccessorImpl.invoke0(Native Method)
at java.base/jdk.internal.reflect.NativeMethodAccessorImpl.invoke(NativeMethodAccessorImpl.java:62)
at java.base/jdk.internal.reflect.DelegatingMethodAccessorImpl.invoke(DelegatingMethodAccessorImpl.java:43)
at java.base/java.lang.reflect.Method.invoke(Method.java:566)
at org.testng.internal.MethodInvocationHelper.invokeMethod(MethodInvocationHelper.java:133)
at org.testng.internal.MethodInvocationHelper.invokeMethodConsideringTimeout(MethodInvocationHelper.java:62)
at org.testng.internal.ConfigInvoker.invokeConfigurationMethod(ConfigInvoker.java:385)
at org.testng.internal.ConfigInvoker.invokeConfigurations(ConfigInvoker.java:321)
at org.testng.internal.TestMethodWorker.invokeBeforeClassMethods(TestMethodWorker.java:176)
at org.testng.internal.TestMethodWorker.run(TestMethodWorker.java:122)
at java.base/java.util.ArrayList.forEach(ArrayList.java:1541)
at org.testng.TestRunner.privateRun(TestRunner.java:794)
at org.testng.TestRunner.run(TestRunner.java:596)
at org.testng.SuiteRunner.runTest(SuiteRunner.java:377)
at org.testng.SuiteRunner.runSequentially(SuiteRunner.java:371)
at org.testng.SuiteRunner.privateRun(SuiteRunner.java:332)
at org.testng.SuiteRunner.run(SuiteRunner.java:276)
at org.testng.SuiteRunnerWorker.runSuite(SuiteRunnerWorker.java:53)
at org.testng.SuiteRunnerWorker.run(SuiteRunnerWorker.java:96)
at org.testng.TestNG.runSuitesSequentially(TestNG.java:1212)
at org.testng.TestNG.runSuitesLocally(TestNG.java:1134)
at org.testng.TestNG.runSuites(TestNG.java:1063)
at org.testng.TestNG.run(TestNG.java:1031)
at org.testng.remote.AbstractRemoteTestNG.run(AbstractRemoteTestNG.java:115)
at org.testng.remote.RemoteTestNG.initAndRun(RemoteTestNG.java:251)
at org.testng.remote.RemoteTestNG.main(RemoteTestNG.java:77)
Caused by: groovy.json.JsonException: Lexing failed on line: 1, column: 1, while reading '<', no possible valid JSON value or punctuation could be recognized.
at groovy.json.JsonLexer.nextToken(JsonLexer.java:86)
at groovy.json.JsonLexer$nextToken.call(Unknown Source)
at org.codehaus.groovy.runtime.callsite.CallSiteArray.defaultCall(CallSiteArray.java:47)
at org.codehaus.groovy.runtime.callsite.AbstractCallSite.call(AbstractCallSite.java:125)
at org.codehaus.groovy.runtime.callsite.AbstractCallSite.call(AbstractCallSite.java:130)
at io.restassured.internal.path.json.ConfigurableJsonSlurper.parse(ConfigurableJsonSlurper.groovy:97)
at io.restassured.internal.path.json.ConfigurableJsonSlurper$parse.callCurrent(Unknown Source)
at org.codehaus.groovy.runtime.callsite.CallSiteArray.defaultCallCurrent(CallSiteArray.java:51)
at org.codehaus.groovy.runtime.callsite.AbstractCallSite.callCurrent(AbstractCallSite.java:171)
at org.codehaus.groovy.runtime.callsite.AbstractCallSite.callCurrent(AbstractCallSite.java:185)
at io.restassured.internal.path.json.ConfigurableJsonSlurper.parseText(ConfigurableJsonSlurper.groovy:83)
at io.restassured.path.json.JsonPath$4$1.method(JsonPath.java:965)
at io.restassured.path.json.JsonPath$ExceptionCatcher.invoke(JsonPath.java:1000)
... 30 more
]]>
            </full-stacktrace>
          </exception> <!-- io.restassured.path.json.exception.JsonPathException -->
          <reporter-output>
          </reporter-output>
        </test-method> <!-- validateResponseTime -->
        <test-method signature="validateStatusCode()[pri:0, instance:com.employeeAPI.testCases.DeleteEmployee@3b6ddd1d]" started-at="2022-02-03T01:18:25 IST" name="validateStatusCode" finished-at="2022-02-03T01:18:25 IST" duration-ms="0" status="SKIP">
          <exception class="io.restassured.path.json.exception.JsonPathException">
            <message>
              <![CDATA[Failed to parse the JSON document]]>
            </message>
            <full-stacktrace>
              <![CDATA[io.restassured.path.json.exception.JsonPathException: Failed to parse the JSON document
at io.restassured.path.json.JsonPath$ExceptionCatcher.invoke(JsonPath.java:1002)
at io.restassured.path.json.JsonPath$4.doParseWith(JsonPath.java:967)
at io.restassured.path.json.JsonPath$JsonParser.parseWith(JsonPath.java:1047)
at io.restassured.path.json.JsonPath.get(JsonPath.java:202)
at com.employeeAPI.testCases.DeleteEmployee.deleteEmployee(DeleteEmployee.java:24)
at java.base/jdk.internal.reflect.NativeMethodAccessorImpl.invoke0(Native Method)
at java.base/jdk.internal.reflect.NativeMethodAccessorImpl.invoke(NativeMethodAccessorImpl.java:62)
at java.base/jdk.internal.reflect.DelegatingMethodAccessorImpl.invoke(DelegatingMethodAccessorImpl.java:43)
at java.base/java.lang.reflect.Method.invoke(Method.java:566)
at org.testng.internal.MethodInvocationHelper.invokeMethod(MethodInvocationHelper.java:133)
at org.testng.internal.MethodInvocationHelper.invokeMethodConsideringTimeout(MethodInvocationHelper.java:62)
at org.testng.internal.ConfigInvoker.invokeConfigurationMethod(ConfigInvoker.java:385)
at org.testng.internal.ConfigInvoker.invokeConfigurations(ConfigInvoker.java:321)
at org.testng.internal.TestMethodWorker.invokeBeforeClassMethods(TestMethodWorker.java:176)
at org.testng.internal.TestMethodWorker.run(TestMethodWorker.java:122)
at java.base/java.util.ArrayList.forEach(ArrayList.java:1541)
at org.testng.TestRunner.privateRun(TestRunner.java:794)
at org.testng.TestRunner.run(TestRunner.java:596)
at org.testng.SuiteRunner.runTest(SuiteRunner.java:377)
at org.testng.SuiteRunner.runSequentially(SuiteRunner.java:371)
at org.testng.SuiteRunner.privateRun(SuiteRunner.java:332)
at org.testng.SuiteRunner.run(SuiteRunner.java:276)
at org.testng.SuiteRunnerWorker.runSuite(SuiteRunnerWorker.java:53)
at org.testng.SuiteRunnerWorker.run(SuiteRunnerWorker.java:96)
at org.testng.TestNG.runSuitesSequentially(TestNG.java:1212)
at org.testng.TestNG.runSuitesLocally(TestNG.java:1134)
at org.testng.TestNG.runSuites(TestNG.java:1063)
at org.testng.TestNG.run(TestNG.java:1031)
at org.testng.remote.AbstractRemoteTestNG.run(AbstractRemoteTestNG.java:115)
at org.testng.remote.RemoteTestNG.initAndRun(RemoteTestNG.java:251)
at org.testng.remote.RemoteTestNG.main(RemoteTestNG.java:77)
Caused by: groovy.json.JsonException: Lexing failed on line: 1, column: 1, while reading '<', no possible valid JSON value or punctuation could be recognized.
at groovy.json.JsonLexer.nextToken(JsonLexer.java:86)
at groovy.json.JsonLexer$nextToken.call(Unknown Source)
at org.codehaus.groovy.runtime.callsite.CallSiteArray.defaultCall(CallSiteArray.java:47)
at org.codehaus.groovy.runtime.callsite.AbstractCallSite.call(AbstractCallSite.java:125)
at org.codehaus.groovy.runtime.callsite.AbstractCallSite.call(AbstractCallSite.java:130)
at io.restassured.internal.path.json.ConfigurableJsonSlurper.parse(ConfigurableJsonSlurper.groovy:97)
at io.restassured.internal.path.json.ConfigurableJsonSlurper$parse.callCurrent(Unknown Source)
at org.codehaus.groovy.runtime.callsite.CallSiteArray.defaultCallCurrent(CallSiteArray.java:51)
at org.codehaus.groovy.runtime.callsite.AbstractCallSite.callCurrent(AbstractCallSite.java:171)
at org.codehaus.groovy.runtime.callsite.AbstractCallSite.callCurrent(AbstractCallSite.java:185)
at io.restassured.internal.path.json.ConfigurableJsonSlurper.parseText(ConfigurableJsonSlurper.groovy:83)
at io.restassured.path.json.JsonPath$4$1.method(JsonPath.java:965)
at io.restassured.path.json.JsonPath$ExceptionCatcher.invoke(JsonPath.java:1000)
... 30 more
]]>
            </full-stacktrace>
          </exception> <!-- io.restassured.path.json.exception.JsonPathException -->
          <reporter-output>
          </reporter-output>
        </test-method> <!-- validateStatusCode -->
        <test-method is-config="true" signature="tearDown()[pri:0, instance:com.employeeAPI.testCases.DeleteEmployee@3b6ddd1d]" started-at="2022-02-03T01:18:25 IST" name="tearDown" finished-at="1970-01-01T05:30:00 IST" duration-ms="-1643831305310" status="SKIP">
          <reporter-output>
          </reporter-output>
        </test-method> <!-- tearDown -->
      </class> <!-- com.employeeAPI.testCases.DeleteEmployee -->
      <class name="com.employeeAPI.testCases.GetSingleEmployee">
        <test-method is-config="true" signature="setUp()[pri:0, instance:com.employeeAPI.testCases.GetSingleEmployee@28f2a10f]" started-at="2022-02-03T01:18:13 IST" name="setUp" finished-at="2022-02-03T01:18:13 IST" duration-ms="4" status="PASS">
          <reporter-output>
          </reporter-output>
        </test-method> <!-- setUp -->
        <test-method is-config="true" signature="getSingleEmployee()[pri:0, instance:com.employeeAPI.testCases.GetSingleEmployee@28f2a10f]" started-at="2022-02-03T01:18:13 IST" name="getSingleEmployee" finished-at="2022-02-03T01:18:17 IST" duration-ms="4247" status="PASS">
          <reporter-output>
          </reporter-output>
        </test-method> <!-- getSingleEmployee -->
        <test-method signature="validateResponseBody()[pri:0, instance:com.employeeAPI.testCases.GetSingleEmployee@28f2a10f]" started-at="2022-02-03T01:18:17 IST" name="validateResponseBody" finished-at="2022-02-03T01:18:17 IST" duration-ms="2" status="PASS">
          <reporter-output>
          </reporter-output>
        </test-method> <!-- validateResponseBody -->
        <test-method signature="validateResponseTime()[pri:0, instance:com.employeeAPI.testCases.GetSingleEmployee@28f2a10f]" started-at="2022-02-03T01:18:17 IST" name="validateResponseTime" finished-at="2022-02-03T01:18:17 IST" duration-ms="3" status="PASS">
          <reporter-output>
          </reporter-output>
        </test-method> <!-- validateResponseTime -->
        <test-method signature="validateStatusCode()[pri:0, instance:com.employeeAPI.testCases.GetSingleEmployee@28f2a10f]" started-at="2022-02-03T01:18:17 IST" name="validateStatusCode" finished-at="2022-02-03T01:18:17 IST" duration-ms="2" status="PASS">
          <reporter-output>
          </reporter-output>
        </test-method> <!-- validateStatusCode -->
        <test-method is-config="true" signature="tearDown()[pri:0, instance:com.employeeAPI.testCases.GetSingleEmployee@28f2a10f]" started-at="2022-02-03T01:18:17 IST" name="tearDown" finished-at="2022-02-03T01:18:17 IST" duration-ms="2" status="PASS">
          <reporter-output>
          </reporter-output>
        </test-method> <!-- tearDown -->
      </class> <!-- com.employeeAPI.testCases.GetSingleEmployee -->
      <class name="com.employeeAPI.testCases.CreateEmployee">
        <test-method is-config="true" signature="setUp()[pri:0, instance:com.employeeAPI.testCases.CreateEmployee@7205765b]" started-at="2022-02-03T01:18:17 IST" name="setUp" finished-at="2022-02-03T01:18:17 IST" duration-ms="3" status="PASS">
          <reporter-output>
          </reporter-output>
        </test-method> <!-- setUp -->
        <test-method is-config="true" signature="createEmployees()[pri:0, instance:com.employeeAPI.testCases.CreateEmployee@7205765b]" started-at="2022-02-03T01:18:17 IST" name="createEmployees" finished-at="2022-02-03T01:18:20 IST" duration-ms="2089" status="PASS">
          <reporter-output>
          </reporter-output>
        </test-method> <!-- createEmployees -->
        <test-method signature="validateResponseBody()[pri:0, instance:com.employeeAPI.testCases.CreateEmployee@7205765b]" started-at="2022-02-03T01:18:20 IST" name="validateResponseBody" finished-at="2022-02-03T01:18:20 IST" duration-ms="2" status="FAIL">
          <exception class="java.lang.AssertionError">
            <message>
              <![CDATA[expected [true] but found [false]]]>
            </message>
            <full-stacktrace>
              <![CDATA[java.lang.AssertionError: expected [true] but found [false]
at org.testng.Assert.fail(Assert.java:99)
at org.testng.Assert.failNotEquals(Assert.java:1037)
at org.testng.Assert.assertTrue(Assert.java:45)
at org.testng.Assert.assertTrue(Assert.java:55)
at com.employeeAPI.testCases.CreateEmployee.validateResponseBody(CreateEmployee.java:47)
at java.base/jdk.internal.reflect.NativeMethodAccessorImpl.invoke0(Native Method)
at java.base/jdk.internal.reflect.NativeMethodAccessorImpl.invoke(NativeMethodAccessorImpl.java:62)
at java.base/jdk.internal.reflect.DelegatingMethodAccessorImpl.invoke(DelegatingMethodAccessorImpl.java:43)
at java.base/java.lang.reflect.Method.invoke(Method.java:566)
at org.testng.internal.MethodInvocationHelper.invokeMethod(MethodInvocationHelper.java:133)
at org.testng.internal.TestInvoker.invokeMethod(TestInvoker.java:598)
at org.testng.internal.TestInvoker.invokeTestMethod(TestInvoker.java:173)
at org.testng.internal.MethodRunner.runInSequence(MethodRunner.java:46)
at org.testng.internal.TestInvoker$MethodInvocationAgent.invoke(TestInvoker.java:824)
at org.testng.internal.TestInvoker.invokeTestMethods(TestInvoker.java:146)
at org.testng.internal.TestMethodWorker.invokeTestMethods(TestMethodWorker.java:146)
at org.testng.internal.TestMethodWorker.run(TestMethodWorker.java:128)
at java.base/java.util.ArrayList.forEach(ArrayList.java:1541)
at org.testng.TestRunner.privateRun(TestRunner.java:794)
at org.testng.TestRunner.run(TestRunner.java:596)
at org.testng.SuiteRunner.runTest(SuiteRunner.java:377)
at org.testng.SuiteRunner.runSequentially(SuiteRunner.java:371)
at org.testng.SuiteRunner.privateRun(SuiteRunner.java:332)
at org.testng.SuiteRunner.run(SuiteRunner.java:276)
at org.testng.SuiteRunnerWorker.runSuite(SuiteRunnerWorker.java:53)
at org.testng.SuiteRunnerWorker.run(SuiteRunnerWorker.java:96)
at org.testng.TestNG.runSuitesSequentially(TestNG.java:1212)
at org.testng.TestNG.runSuitesLocally(TestNG.java:1134)
at org.testng.TestNG.runSuites(TestNG.java:1063)
at org.testng.TestNG.run(TestNG.java:1031)
at org.testng.remote.AbstractRemoteTestNG.run(AbstractRemoteTestNG.java:115)
at org.testng.remote.RemoteTestNG.initAndRun(RemoteTestNG.java:251)
at org.testng.remote.RemoteTestNG.main(RemoteTestNG.java:77)
]]>
            </full-stacktrace>
          </exception> <!-- java.lang.AssertionError -->
          <reporter-output>
          </reporter-output>
        </test-method> <!-- validateResponseBody -->
        <test-method signature="validateResponseTime()[pri:0, instance:com.employeeAPI.testCases.CreateEmployee@7205765b]" started-at="2022-02-03T01:18:20 IST" name="validateResponseTime" finished-at="2022-02-03T01:18:20 IST" duration-ms="4" status="PASS">
          <reporter-output>
          </reporter-output>
        </test-method> <!-- validateResponseTime -->
        <test-method signature="validateStatusCode()[pri:0, instance:com.employeeAPI.testCases.CreateEmployee@7205765b]" started-at="2022-02-03T01:18:20 IST" name="validateStatusCode" finished-at="2022-02-03T01:18:20 IST" duration-ms="2" status="FAIL">
          <exception class="java.lang.AssertionError">
            <message>
              <![CDATA[expected [200] but found [429]]]>
            </message>
            <full-stacktrace>
              <![CDATA[java.lang.AssertionError: expected [200] but found [429]
at org.testng.Assert.fail(Assert.java:99)
at org.testng.Assert.failNotEquals(Assert.java:1037)
at org.testng.Assert.assertEqualsImpl(Assert.java:140)
at org.testng.Assert.assertEquals(Assert.java:122)
at org.testng.Assert.assertEquals(Assert.java:907)
at org.testng.Assert.assertEquals(Assert.java:917)
at com.employeeAPI.testCases.CreateEmployee.validateStatusCode(CreateEmployee.java:58)
at java.base/jdk.internal.reflect.NativeMethodAccessorImpl.invoke0(Native Method)
at java.base/jdk.internal.reflect.NativeMethodAccessorImpl.invoke(NativeMethodAccessorImpl.java:62)
at java.base/jdk.internal.reflect.DelegatingMethodAccessorImpl.invoke(DelegatingMethodAccessorImpl.java:43)
at java.base/java.lang.reflect.Method.invoke(Method.java:566)
at org.testng.internal.MethodInvocationHelper.invokeMethod(MethodInvocationHelper.java:133)
at org.testng.internal.TestInvoker.invokeMethod(TestInvoker.java:598)
at org.testng.internal.TestInvoker.invokeTestMethod(TestInvoker.java:173)
at org.testng.internal.MethodRunner.runInSequence(MethodRunner.java:46)
at org.testng.internal.TestInvoker$MethodInvocationAgent.invoke(TestInvoker.java:824)
at org.testng.internal.TestInvoker.invokeTestMethods(TestInvoker.java:146)
at org.testng.internal.TestMethodWorker.invokeTestMethods(TestMethodWorker.java:146)
at org.testng.internal.TestMethodWorker.run(TestMethodWorker.java:128)
at java.base/java.util.ArrayList.forEach(ArrayList.java:1541)
at org.testng.TestRunner.privateRun(TestRunner.java:794)
at org.testng.TestRunner.run(TestRunner.java:596)
at org.testng.SuiteRunner.runTest(SuiteRunner.java:377)
at org.testng.SuiteRunner.runSequentially(SuiteRunner.java:371)
at org.testng.SuiteRunner.privateRun(SuiteRunner.java:332)
at org.testng.SuiteRunner.run(SuiteRunner.java:276)
at org.testng.SuiteRunnerWorker.runSuite(SuiteRunnerWorker.java:53)
at org.testng.SuiteRunnerWorker.run(SuiteRunnerWorker.java:96)
at org.testng.TestNG.runSuitesSequentially(TestNG.java:1212)
at org.testng.TestNG.runSuitesLocally(TestNG.java:1134)
at org.testng.TestNG.runSuites(TestNG.java:1063)
at org.testng.TestNG.run(TestNG.java:1031)
at org.testng.remote.AbstractRemoteTestNG.run(AbstractRemoteTestNG.java:115)
at org.testng.remote.RemoteTestNG.initAndRun(RemoteTestNG.java:251)
at org.testng.remote.RemoteTestNG.main(RemoteTestNG.java:77)
]]>
            </full-stacktrace>
          </exception> <!-- java.lang.AssertionError -->
          <reporter-output>
          </reporter-output>
        </test-method> <!-- validateStatusCode -->
        <test-method is-config="true" signature="tearDown()[pri:0, instance:com.employeeAPI.testCases.CreateEmployee@7205765b]" started-at="2022-02-03T01:18:20 IST" name="tearDown" finished-at="2022-02-03T01:18:20 IST" duration-ms="0" status="PASS">
          <reporter-output>
          </reporter-output>
        </test-method> <!-- tearDown -->
      </class> <!-- com.employeeAPI.testCases.CreateEmployee -->
    </test> <!-- EmployeesRestAPITests -->
  </suite> <!-- EmployeesRestAPISuite -->
</testng-results>
